<?xml version="1.0" encoding="UTF-8"?>
<!-- Generated by org.testng.reporters.JUnitReportReporter -->
<testsuite skipped="1" hostname="DESKTOP-NUOK5F5" name="FrameWork.TestNG.LoginTest" tests="4" failures="1" timestamp="02 Jun 2019 16:00:11 GMT" time="22.368" errors="1">
  <testcase name="testTheLoginBtn" time="4.278" classname="FrameWork.TestNG.LoginTest">
    <failure type="java.lang.AssertionError" message="expected [The app did not log in] but found [My Account]">
      <![CDATA[java.lang.AssertionError: expected [The app did not log in] but found [My Account]
at org.testng.Assert.fail(Assert.java:96)
at org.testng.Assert.failNotEquals(Assert.java:776)
at org.testng.Assert.assertEqualsImpl(Assert.java:137)
at org.testng.Assert.assertEquals(Assert.java:118)
at org.testng.Assert.assertEquals(Assert.java:453)
at org.testng.Assert.assertEquals(Assert.java:463)
at FrameWork.TestNG.LoginTest.testTheLoginBtn(LoginTest.java:27)
at sun.reflect.NativeMethodAccessorImpl.invoke0(Native Method)
at sun.reflect.NativeMethodAccessorImpl.invoke(Unknown Source)
at sun.reflect.DelegatingMethodAccessorImpl.invoke(Unknown Source)
at java.lang.reflect.Method.invoke(Unknown Source)
at org.testng.internal.MethodInvocationHelper.invokeMethod(MethodInvocationHelper.java:124)
at org.testng.internal.Invoker.invokeMethod(Invoker.java:583)
at org.testng.internal.Invoker.invokeTestMethod(Invoker.java:719)
at org.testng.internal.Invoker.invokeTestMethods(Invoker.java:989)
at org.testng.internal.TestMethodWorker.invokeTestMethods(TestMethodWorker.java:125)
at org.testng.internal.TestMethodWorker.run(TestMethodWorker.java:109)
at org.testng.TestRunner.privateRun(TestRunner.java:648)
at org.testng.TestRunner.run(TestRunner.java:505)
at org.testng.SuiteRunner.runTest(SuiteRunner.java:455)
at org.testng.SuiteRunner.runSequentially(SuiteRunner.java:450)
at org.testng.SuiteRunner.privateRun(SuiteRunner.java:415)
at org.testng.SuiteRunner.run(SuiteRunner.java:364)
at org.testng.SuiteRunnerWorker.runSuite(SuiteRunnerWorker.java:52)
at org.testng.SuiteRunnerWorker.run(SuiteRunnerWorker.java:84)
at org.testng.TestNG.runSuitesSequentially(TestNG.java:1208)
at org.testng.TestNG.runSuitesLocally(TestNG.java:1137)
at org.testng.TestNG.runSuites(TestNG.java:1049)
at org.testng.TestNG.run(TestNG.java:1017)
at org.testng.remote.AbstractRemoteTestNG.run(AbstractRemoteTestNG.java:115)
at org.testng.remote.RemoteTestNG.initAndRun(RemoteTestNG.java:251)
at org.testng.remote.RemoteTestNG.main(RemoteTestNG.java:77)
]]>
    </failure>
  </testcase> <!-- testTheLoginBtn -->
  <testcase name="infinitFailure" time="9.760" classname="FrameWork.TestNG.LoginTest">
    <error type="org.testng.internal.thread.ThreadTimeoutException" message="Method FrameWork.TestNG.LoginTest.infinitFailure() didn&#039;t finish within the time-out 5000">
      <![CDATA[org.testng.internal.thread.ThreadTimeoutException: Method FrameWork.TestNG.LoginTest.infinitFailure() didn't finish within the time-out 5000
at java.io.FileOutputStream.writeBytes(Native Method)
at java.io.FileOutputStream.write(Unknown Source)
at java.io.BufferedOutputStream.flushBuffer(Unknown Source)
at java.io.BufferedOutputStream.flush(Unknown Source)
at java.io.PrintStream.write(Unknown Source)
at sun.nio.cs.StreamEncoder.writeBytes(Unknown Source)
at sun.nio.cs.StreamEncoder.implFlushBuffer(Unknown Source)
at sun.nio.cs.StreamEncoder.flushBuffer(Unknown Source)
at java.io.OutputStreamWriter.flushBuffer(Unknown Source)
at java.io.PrintStream.newLine(Unknown Source)
at java.io.PrintStream.println(Unknown Source)
at FrameWork.TestNG.LoginTest.infinitFailure(LoginTest.java:60)
at sun.reflect.NativeMethodAccessorImpl.invoke0(Native Method)
at sun.reflect.NativeMethodAccessorImpl.invoke(Unknown Source)
at sun.reflect.DelegatingMethodAccessorImpl.invoke(Unknown Source)
at java.lang.reflect.Method.invoke(Unknown Source)
at org.testng.internal.MethodInvocationHelper.invokeMethod(MethodInvocationHelper.java:124)
at org.testng.internal.InvokeMethodRunnable.runOne(InvokeMethodRunnable.java:54)
at org.testng.internal.InvokeMethodRunnable.run(InvokeMethodRunnable.java:44)
at java.util.concurrent.Executors$RunnableAdapter.call(Unknown Source)
at java.util.concurrent.FutureTask.run(Unknown Source)
at java.util.concurrent.ThreadPoolExecutor.runWorker(Unknown Source)
at java.util.concurrent.ThreadPoolExecutor$Worker.run(Unknown Source)
at java.lang.Thread.run(Unknown Source)
]]>
    </error>
  </testcase> <!-- infinitFailure -->
  <testcase name="testLogIn2" time="8.330" classname="FrameWork.TestNG.LoginTest"/>
  <testcase name="testLogIn" time="0.000" classname="FrameWork.TestNG.LoginTest">
    <skipped/>
  </testcase> <!-- testLogIn -->
</testsuite> <!-- FrameWork.TestNG.LoginTest -->
